Starting script...
Traceback (most recent call last):
  File "C:\Users\nehad\PycharmProjects\MetropolisWebInterfacebatch/metro_app/batch_run.py", line 55, in <module>
    functions.traveler_zip_file(sim, batch_run.zip_file)
  File "C:\Users\nehad\PycharmProjects\MetropolisWebInterfacebatch\metro_app\functions.py", line 423, in traveler_zip_file
    file = zipfile.ZipFile(file)
  File "C:\Users\nehad\AppData\Local\Programs\Python\Python38\lib\zipfile.py", line 1269, in __init__
    self._RealGetContents()
  File "C:\Users\nehad\AppData\Local\Programs\Python\Python38\lib\zipfile.py", line 1332, in _RealGetContents
    endrec = _EndRecData(fp)
  File "C:\Users\nehad\AppData\Local\Programs\Python\Python38\lib\zipfile.py", line 264, in _EndRecData
    fpin.seek(0, 2)
  File "C:\Users\nehad\PycharmProjects\MetropolisWebInterfacebatch\batchtest\lib\site-packages\django\core\files\utils.py", line 20, in <lambda>
    seek = property(lambda self: self.file.seek)
  File "C:\Users\nehad\PycharmProjects\MetropolisWebInterfacebatch\batchtest\lib\site-packages\django\db\models\fields\files.py", line 41, in _get_file
    self._require_file()
  File "C:\Users\nehad\PycharmProjects\MetropolisWebInterfacebatch\batchtest\lib\site-packages\django\db\models\fields\files.py", line 38, in _require_file
    raise ValueError("The '%s' attribute has no file associated with it." % self.field.name)
ValueError: The 'zip_file' attribute has no file associated with it.
